Workbook
Name lut: 'simple random sample'!$L$6:$O$1005

Sheet simple random sample
A1: Question | C1: Answer
A2: A simple random sample (n=150) is to be drawn from the population statistics of the city of Kickritspotschn (N=1.000). | C2: → Determination of 150 random numbers between 1 and 1,000 (= ID numbers of the persons to be selected)
E3: Nr. | F3: Variant 1 | G3: Variant 2 | H3: Surname | I3: Familiyname | J3: Address | L3: List of the population
C4: # Variant 1: | E4: 1 | F4: =RANDBETWEEN(1,1000) -> 356 | G4: 694 | H4: =VLOOKUP($G4,lut,2,FALSE) -> Lena | I4: =VLOOKUP($G4,lut,3,FALSE) -> Fischer | J4: =VLOOKUP($G4,lut,4,FALSE) -> Gartenweg 14E, Stg. 3, Tür 2, 2100 Korneuburg, Österreich
C5: Excel - random range, random number | E5: 2 | F5: =RANDBETWEEN(1,1000) -> 507 | G5: 23 | H5: =VLOOKUP($G5,lut,2,FALSE) -> Laura | I5: =VLOOKUP($G5,lut,3,FALSE) -> Zimmermann | J5: =VLOOKUP($G5,lut,4,FALSE) -> Mühlweg 55, 6900 Bregenz, Österreich | L5: Nr. | M5: Surname | N5: Familiyname | O5: Address
C6: (may contain duplicate values) | E6: 3 | F6: =RANDBETWEEN(1,1000) -> 41 | G6: 139 | H6: =VLOOKUP($G6,lut,2,FALSE) -> Noah | I6: =VLOOKUP($G6,lut,3,FALSE) -> Hofer | J6: =VLOOKUP($G6,lut,4,FALSE) -> WaldMühlgasse 151, 1060 Wien, Österreich | L6: 1 | M6: Verena | N6: Hofer | O6: Waldring 58A, 5020 Salzburg, Österreich
E7: 4 | F7: =RANDBETWEEN(1,1000) -> 852 | G7: 742 | H7: =VLOOKUP($G7,lut,2,FALSE) -> Johanna | I7: =VLOOKUP($G7,lut,3,FALSE) -> Brunner | J7: =VLOOKUP($G7,lut,4,FALSE) -> Mühlgasse 10, 6020 Innsbruck, Österreich | L7: 2 | M7: Eva | N7: Steiner | O7: OpernKirchenplatz 56, Stg. 2, Tür 35, 4020 Linz, Österreich
C8: # Option 2: Random number generator | E8: 5 | F8: =RANDBETWEEN(1,1000) -> 741 | G8: 688 | H8: =VLOOKUP($G8,lut,2,FALSE) -> Maximilian | I8: =VLOOKUP($G8,lut,3,FALSE) -> Schuster | J8: =VLOOKUP($G8,lut,4,FALSE) -> Mühlgasse 20, 6020 Innsbruck, Österreich | L8: 3 | M8: Theresa | N8: Maier | O8: Mariahilferallee 2, 1060 Wien, Österreich
C9: http://www.random.org | E9: 6 | F9: =RANDBETWEEN(1,1000) -> 280 | G9: 638 | H9: =VLOOKUP($G9,lut,2,FALSE) -> Melanie | I9: =VLOOKUP($G9,lut,3,FALSE) -> Maier | J9: =VLOOKUP($G9,lut,4,FALSE) -> EichenKirchenring 177, 1050 Wien, Österreich | L9: 4 | M9: Maximilian | N9: Berger | O9: Feldgasse 87D, 1040 Wien, Österreich
C10: (Numbers-Integer Sets, without duplicate values) | E10: 7 | F10: =RANDBETWEEN(1,1000) -> 242 | G10: 595 | H10: =VLOOKUP($G10,lut,2,FALSE) -> Nina | I10: =VLOOKUP($G10,lut,3,FALSE) -> Richter | J10: =VLOOKUP($G10,lut,4,FALSE) -> Ahornstraße 94, 1080 Wien, Österreich | L10: 5 | M10: Lea | N10: Koch | O10: SeeDonaukai 138D, 1030 Wien, Österreich
E11: 8 | F11: =RANDBETWEEN(1,1000) -> 802 | G11: 495 | H11: =VLOOKUP($G11,lut,2,FALSE) -> Franz | I11: =VLOOKUP($G11,lut,3,FALSE) -> Schuster | J11: =VLOOKUP($G11,lut,4,FALSE) -> Döblingerstraße 54, 8010 Graz, Österreich | L11: 6 | M11: Verena | N11: Lindner | O11: IndustrieBahnhofallee 12, 8010 Graz, Österreich
E12: 9 | F12: =RANDBETWEEN(1,1000) -> 173 | G12: 612 | H12: =VLOOKUP($G12,lut,2,FALSE) -> Sophie | I12: =VLOOKUP($G12,lut,3,FALSE) -> Koch | J12: =VLOOKUP($G12,lut,4,FALSE) -> Marktstraße 148, Stg. 3, Tür 23, 8010 Graz, Österreich | L12: 7 | M12: Paul | N12: Maier | O12: Schlossplatz 163, 1060 Wien, Österreich
E13: 10 | F13: =RANDBETWEEN(1,1000) -> 384 | G13: 596 | H13: =VLOOKUP($G13,lut,2,FALSE) -> Laura | I13: =VLOOKUP($G13,lut,3,FALSE) -> Stark | J13: =VLOOKUP($G13,lut,4,FALSE) -> Döblingerkai 135, 8010 Graz, Österreich | L13: 8 | M13: Elias | N13: Stark | O13: Ringring 166F, 1060 Wien, Österreich
E14: 11 | F14: =RANDBETWEEN(1,1000) -> 933 | G14: 595 | H14: =VLOOKUP($G14,lut,2,FALSE) -> Nina | I14: =VLOOKUP($G14,lut,3,FALSE) -> Richter | J14: =VLOOKUP($G14,lut,4,FALSE) -> Ahornstraße 94, 1080 Wien, Österreich | L14: 9 | M14: Jonas | N14: Weber | O14: Donauplatz 164, 1080 Wien, Österreich
E15: 12 | F15: =RANDBETWEEN(1,1000) -> 98 | G15: 7 | H15: =VLOOKUP($G15,lut,2,FALSE) -> Paul | I15: =VLOOKUP($G15,lut,3,FALSE) -> Maier | J15: =VLOOKUP($G15,lut,4,FALSE) -> Schlossplatz 163, 1060 Wien, Österreich | L15: 10 | M15: Franz | N15: Jäger | O15: Gartengasse 81, 1030 Wien, Österreich
E16: 13 | F16: =RANDBETWEEN(1,1000) -> 613 | G16: 286 | H16: =VLOOKUP($G16,lut,2,FALSE) -> Felix | I16: =VLOOKUP($G16,lut,3,FALSE) -> Leitner | J16: =VLOOKUP($G16,lut,4,FALSE) -> Lindenallee 91, Stg. 4, Tür 30, 2380 Perchtoldsdorf, Österreich | L16: 11 | M16: Lisa | N16: König | O16: Parkgasse 102, 4600 Wels, Österreich
E17: 14 | F17: =RANDBETWEEN(1,1000) -> 230 | G17: 157 | H17: =VLOOKUP($G17,lut,2,FALSE) -> Lea | I17: =VLOOKUP($G17,lut,3,FALSE) -> Kraus | J17: =VLOOKUP($G17,lut,4,FALSE) -> Wiesenweg 152, 5020 Salzburg, Österreich | L17: 12 | M17: Julia | N17: Bauer | O17: Mühlring 68, 2500 Baden, Österreich
E18: 15 | F18: =RANDBETWEEN(1,1000) -> 109 | G18: 908 | H18: =VLOOKUP($G18,lut,2,FALSE) -> Matthias | I18: =VLOOKUP($G18,lut,3,FALSE) -> Maier | J18: =VLOOKUP($G18,lut,4,FALSE) -> Augartenweg 91, 8010 Graz, Österreich | L18: 13 | M18: Philipp | N18: Reiter | O18: Eichengasse 24, Stg. 2, Tür 28, 1040 Wien, Österreich
E19: 16 | F19: =RANDBETWEEN(1,1000) -> 153 | G19: 61 | H19: =VLOOKUP($G19,lut,2,FALSE) -> David | I19: =VLOOKUP($G19,lut,3,FALSE) -> Winkler | J19: =VLOOKUP($G19,lut,4,FALSE) -> ParkFeldallee 60, 1050 Wien, Österreich | L19: 14 | M19: Melanie | N19: Pichler | O19: Mozartplatz 120, 3430 Tulln, Österreich
E20: 17 | F20: =RANDBETWEEN(1,1000) -> 498 | G20: 472 | H20: =VLOOKUP($G20,lut,2,FALSE) -> Georg | I20: =VLOOKUP($G20,lut,3,FALSE) -> Brunner | J20: =VLOOKUP($G20,lut,4,FALSE) -> Flussring 151D, 2700 Wiener Neustadt, Österreich | L20: 15 | M20: Anna | N20: Langer | O20: Wiesenring 69, Stg. 4, Tür 11, 2000 Stockerau, Österreich
E21: 18 | F21: =RANDBETWEEN(1,1000) -> 549 | G21: 445 | H21: =VLOOKUP($G21,lut,2,FALSE) -> Maximilian | I21: =VLOOKUP($G21,lut,3,FALSE) -> Kaiser | J21: =VLOOKUP($G21,lut,4,FALSE) -> PromenadeSchubertkai 5, 6900 Bregenz, Österreich | L21: 16 | M21: Florian | N21: Huber | O21: Seeallee 130, 4600 Wels, Österreich
E22: 19 | F22: =RANDBETWEEN(1,1000) -> 893 | G22: 291 | H22: =VLOOKUP($G22,lut,2,FALSE) -> Marie | I22: =VLOOKUP($G22,lut,3,FALSE) -> Schmid | J22: =VLOOKUP($G22,lut,4,FALSE) -> Parkstraße 151F, 2380 Perchtoldsdorf, Österreich | L22: 17 | M22: Verena | N22: Zimmermann | O22: UniversitätsRosengasse 139, 3300 Amstetten, Österreich
... E153: 150 | F153: =RANDBETWEEN(1,1000) -> 923 | G153: 674 | H153: =VLOOKUP($G153,lut,2,FALSE) -> Marie | I153: =VLOOKUP($G153,lut,3,FALSE) -> Seidl | J153: =VLOOKUP($G153,lut,4,FALSE) -> Mozartring 30A, 5020 Salzburg, Österreich | L153: 148 | M153: Lena | N153: Feldbauer | O153: Gartenallee 144, 1040 Wien, Österreich
E154: 151 | L154: 149 | M154: Helena | N154: Klein | O154: Brucknerkai 14, 4020 Linz, Österreich
E155: 152 | L155: 150 | M155: Sophie | N155: Maierhofer | O155: KärntnerPratergasse 58, 2100 Korneuburg, Österreich
E156: 153 | L156: 151 | M156: Simon | N156: Hofer | O156: RingBrucknerallee 144, 4020 Linz, Österreich
E157: 154 | L157: 152 | M157: Michael | N157: Feldbauer | O157: Waldallee 178, 1060 Wien, Österreich
E158: 155 | L158: 153 | M158: Georg | N158: Eder | O158: AlleeFeldweg 145, Stg. 6, Tür 2, 1030 Wien, Österreich
E159: 156 | L159: 154 | M159: Paul | N159: Vogt | O159: Favoritengasse 117, 2100 Korneuburg, Österreich
E160: 157 | L160: 155 | M160: Katharina | N160: Jäger | O160: RathausGartenallee 40E, 1020 Wien, Österreich
E161: 158 | L161: 156 | M161: David | N161: Hofmann | O161: Brucknerplatz 107, 8010 Graz, Österreich
E162: 159 | L162: 157 | M162: Lea | N162: Kraus | O162: Wiesenweg 152, 5020 Salzburg, Österreich
E163: 160 | L163: 158 | M163: Emma | N163: Haas | O163: UniversitätsMarktstraße 55, 8010 Graz, Österreich
E164: 161 | L164: 159 | M164: Katharina | N164: Hofer | O164: Bergplatz 45E, 6020 Innsbruck, Österreich
E165: 162 | L165: 160 | M165: Matthias | N165: Stark | O165: Promenadestraße 11, 2700 Wiener Neustadt, Österreich
... E503: 500 | L503: 498 | M503: Laura | N503: Maierhofer | O503: Eichenweg 116, 2500 Baden, Österreich
L504: 499 | M504: Nina | N504: Langer | O504: WiesenKreuzallee 17, Stg. 1, Tür 23, 3500 Krems an der Donau, Österreich
L505: 500 | M505: Magdalena | N505: Moser | O505: Hauptkai 156D, 2380 Perchtoldsdorf, Österreich
L506: 501 | M506: Helena | N506: Wagner | O506: Pratergasse 35, 9020 Klagenfurt am Wörthersee, Österreich
L507: 502 | M507: Eva | N507: Fischer | O507: Feldweg 187, 1010 Wien, Österreich
...

Sheet stratified sample 1d
A1: Question | D1: Answer
A2: Draw a proportionally stratified sample (n=250) from the following data set on the population of Tyrol (2001). How many Tyroleans of which age groups do you need to survey?
D3: initial data
D4: BLD | E4: EW_gesamt | F4: < 15 J. | G4: 15 - 40 J. | H4: 40 - 60 J. | I4: 60 - 75 J. | J4: > 75 J.
D5: Tirol 2001 | E5: =SUM(F5:J5) -> 673504 | F5: 123855 | G5: 253054 | H5: 171491 | I5: 84329 | J5: 40775
E9: Sample size n: | F9: 500
D14: BLD | E14: n | F14: < 15 J. | G14: 15 - 40 J. | H14: 40 - 60 J. | I14: 60 - 75 J. | J14: > 75 J.
D15: Tirol 2001 | E15: =SUM(F15:J15) -> 500 | F15: =ROUND((F5/$E$5)*$F$9,0) -> 92 | G15: =ROUND((G5/$E$5)*$F$9,0) -> 188 | H15: =ROUND((H5/$E$5)*$F$9,0) -> 127 | I15: =ROUND((I5/$E$5)*$F$9,0) -> 63 | J15: =ROUND((J5/$E$5)*$F$9,0) -> 30

Sheet stratified sample 2d
A1: Frage | D1: Answer
A2: Draw a proportionally stratified sample (n=200) from the following data set on the population of Lower Austria (2021). How many people of which age & gender groups do you need to survey?
D3: initial data for Lower Austria (2021)
D4: sex | E4: < 15 years | F4: 15 - 64 years | G4: 65+ years
D5: male | E5: ='statcube data'!C14 -> 125819 | F5: ='statcube data'!D14 -> 554706 | G5: ='statcube data'!E14 -> 156496
D6: female | E6: ='statcube data'!C15 -> 119633 | F6: ='statcube data'!D15 -> 546861 | G6: ='statcube data'!E15 -> 195436
E9: Sample size n: | F9: 200
D13: Sample Structure
D14: sex | E14: < 15 years | F14: 15 - 64 years | G14: 65+ years
D15: male | E15: =ROUND((E5/SUM($E$5:$G$6)*$F$9),0) -> 15 | F15: =ROUND((F5/SUM($E$5:$G$6)*$F$9),0) -> 65 | G15: =ROUND((G5/SUM($E$5:$G$6)*$F$9),0) -> 18
D16: female | E16: =ROUND((E6/SUM($E$5:$G$6)*$F$9),0) -> 14 | F16: =ROUND((F6/SUM($E$5:$G$6)*$F$9),0) -> 64 | G16: =ROUND((G6/SUM($E$5:$G$6)*$F$9),0) -> 23

Sheet statcube data
A3: Census Time Series – Persons (Q)
A4: Sex by Year and Age in years (Level +4) by Place of usual residence – Territorial structure of 2021 (Level +2)
A5: Counting: Persons
A7: Filters:
A8: Default Summation | B8: Persons
A9: Place of usual residence – Territorial structure of 2021 (Level +2) | B9: Lower Austria
A11: Year | C11: 2021
A12: Age in years (Level +4) | C12: Under 15 years | D12: 15 to 64 years | E12: 65 years and over
B13: Sex
B14: Male | C14: 125819 | D14: 554706 | E14: 156496
B15: Female | C15: 119633 | D15: 546861 | E15: 195436
A17: Symbol | B17: Description
A19: Q | B19: STATcube – Statistical Database of STATISTICS AUSTRIA
A20: Census Time Series – Persons | B20: The Register-based Censuses 2011 and 2021 are complete surveys on characteristics of the Austrian resident population as per 31/10 and are conducted by using information from administrative registers. The characteristics and definitions are based on the EU regulation on population and housing censuses. The 1991 and 2001 Population Censuses are complete enumerations of the total population by using questionnaires for the reference dates 15/05/1991 and 15/05/2001, respectively. The concept of the censuses is based on the National Population Census Act of 1980 as well as the Census Recommendations of the Conference of European Statisticians. The 2001 Census is also based on the EU-guidelines for the Community programme of population and housing censuses. For the time series database the attributes of the 1991 and 2001 Population Censuses were recoded into the classifications of the Register-based Censuses. A description of the comparability of the censuses is given in the notes of the respective attributes. For further information see: https://www.statistik.at/en/statistics/population-and-society/population/population-stock/historic-censuses https://www.statistik.at/fileadmin/shared/QM/Standarddokumentationen/B_1/std_b_abgestimmte_erwerbsstatistik.pdf (German only) .) Territorial structure of 2021. .) Updating: addition of further years planned last update: [2025-03-20] .) Contact details: Directorate Social Statistics For general enquiries: +43 1 711 28-7070 In case of special enquiries please contact registerzaehlung@statistik.gv.at .) Please note: For data privacy protection reasons, the statistical disclosure control method of "Record Swapping" has been used on a part of the data. For analyses based on very small cell values, no reliable assertions can be made. .) ABO: Data at municipality level is available for subscription users (ABO). https://www.statistik.at/en/databases/statcube/statcube-statistical-database/subscription .) Open Data The portal data.statistik.gv.at offers a range of data sets from the dictionary of official Austrian statistical data. https://data.statistik.gv.at/web/
A21: Sex | B21: In order to guarantee protection of data privacy, persons with a third sex category are not separately reported. They are imputed either as "male" or "female".
A22: Age in years | B22: Age in completed years at the reference day. Calculated from the date of birth.
A23: Place of usual residence – Territorial structure of 2021 [partly ABO] | B23: Refers to the place of residence at the respective reference date according to the Austrian administrative territorial structure valid in 2021. Other Metadata: https://www.statistik.at/services/tools/services/regionales/regionale-gliederungen
